2019-10-28 19:59:52,000 raised exception at 2019-10-28.log: 'Dataset_plots' object has no attribute 'plot_QQ_plot'
Traceback (most recent call last):
  File "<ipython-input-15-638c1fc0d4b6>", line 27, in <module>
    generic_plots_obj.plot_QQ_plot(data)
AttributeError: 'Dataset_plots' object has no attribute 'plot_QQ_plot'
2019-10-28 20:01:43,703 raised exception at 2019-10-28.log: 'Dataset_plots' object has no attribute 'plot_QQ_plot'
Traceback (most recent call last):
  File "<ipython-input-17-1a3a9a0858a8>", line 27, in <module>
    generic_plots_obj.plot_QQ_plot(data)
AttributeError: 'Dataset_plots' object has no attribute 'plot_QQ_plot'
2019-10-28 20:26:36,527 raised exception at 2019-10-28.log: 'Distributions_generator' object has no attribute 'generate_random_distribution'
Traceback (most recent call last):
  File "<ipython-input-3-8f6698fe3b54>", line 3, in <module>
    random_data_1 = dist_generator.generate_random_distribution(20, 1000)
AttributeError: 'Distributions_generator' object has no attribute 'generate_random_distribution'
2019-10-28 20:26:53,734 raised exception at 2019-10-28.log: 'Distributions_generator' object has no attribute 'generate_random_distribution'
Traceback (most recent call last):
  File "<ipython-input-4-8f6698fe3b54>", line 3, in <module>
    random_data_1 = dist_generator.generate_random_distribution(20, 1000)
AttributeError: 'Distributions_generator' object has no attribute 'generate_random_distribution'
2019-10-28 20:27:19,469 raised exception at 2019-10-28.log: 'Distributions_generator' object has no attribute 'generate_random_distribution'
Traceback (most recent call last):
  File "<ipython-input-6-8f6698fe3b54>", line 3, in <module>
    random_data_1 = dist_generator.generate_random_distribution(20, 1000)
AttributeError: 'Distributions_generator' object has no attribute 'generate_random_distribution'
2019-10-28 20:29:00,997 raised exception at 2019-10-28.log: 'Distributions_generator' object has no attribute 'generate_random_distribution'
Traceback (most recent call last):
  File "<ipython-input-7-8f6698fe3b54>", line 3, in <module>
    random_data_1 = dist_generator.generate_random_distribution(20, 1000)
AttributeError: 'Distributions_generator' object has no attribute 'generate_random_distribution'
2019-10-28 20:29:27,084 raised exception at 2019-10-28.log: 'normal_data_1'
Traceback (most recent call last):
  File "C:\Users\gcabreram\AppData\Local\Continuum\anaconda3\lib\site-packages\pandas\core\indexes\base.py", line 2657, in get_loc
    return self._engine.get_loc(key)
  File "pandas/_libs/index.pyx", line 108, in pandas._libs.index.IndexEngine.get_loc
  File "pandas/_libs/index.pyx", line 132, in pandas._libs.index.IndexEngine.get_loc
  File "pandas/_libs/hashtable_class_helper.pxi", line 1601, in pandas._libs.hashtable.PyObjectHashTable.get_item
  File "pandas/_libs/hashtable_class_helper.pxi", line 1608, in pandas._libs.hashtable.PyObjectHashTable.get_item
KeyError: 'normal_data_1'

During handling of the above exception, another exception occurred:

Traceback (most recent call last):
  File "<ipython-input-4-8f6698fe3b54>", line 9, in <module>
    figsize_rows=5, figsize_cols=3)
  File "c:\Users\gcabreram\Documents\DS_validation_experiments\machine_learning_concepts_checks\project\dataset_plots\generic_plots.py", line 71, in plot_series_histogram
    raise exc
  File "c:\Users\gcabreram\Documents\DS_validation_experiments\machine_learning_concepts_checks\project\dataset_plots\generic_plots.py", line 66, in plot_series_histogram
    plt.hist(self.dataframe[attribute])
  File "C:\Users\gcabreram\AppData\Local\Continuum\anaconda3\lib\site-packages\pandas\core\frame.py", line 2927, in __getitem__
    indexer = self.columns.get_loc(key)
  File "C:\Users\gcabreram\AppData\Local\Continuum\anaconda3\lib\site-packages\pandas\core\indexes\base.py", line 2659, in get_loc
    return self._engine.get_loc(self._maybe_cast_indexer(key))
  File "pandas/_libs/index.pyx", line 108, in pandas._libs.index.IndexEngine.get_loc
  File "pandas/_libs/index.pyx", line 132, in pandas._libs.index.IndexEngine.get_loc
  File "pandas/_libs/hashtable_class_helper.pxi", line 1601, in pandas._libs.hashtable.PyObjectHashTable.get_item
  File "pandas/_libs/hashtable_class_helper.pxi", line 1608, in pandas._libs.hashtable.PyObjectHashTable.get_item
KeyError: 'normal_data_1'
2019-10-28 20:29:39,380 raised exception at 2019-10-28.log: 'normal_data_1'
Traceback (most recent call last):
  File "C:\Users\gcabreram\AppData\Local\Continuum\anaconda3\lib\site-packages\pandas\core\indexes\base.py", line 2657, in get_loc
    return self._engine.get_loc(key)
  File "pandas/_libs/index.pyx", line 108, in pandas._libs.index.IndexEngine.get_loc
  File "pandas/_libs/index.pyx", line 132, in pandas._libs.index.IndexEngine.get_loc
  File "pandas/_libs/hashtable_class_helper.pxi", line 1601, in pandas._libs.hashtable.PyObjectHashTable.get_item
  File "pandas/_libs/hashtable_class_helper.pxi", line 1608, in pandas._libs.hashtable.PyObjectHashTable.get_item
KeyError: 'normal_data_1'

During handling of the above exception, another exception occurred:

Traceback (most recent call last):
  File "<ipython-input-5-156882af8b8f>", line 9, in <module>
    figsize_rows=5, figsize_cols=3)
  File "c:\Users\gcabreram\Documents\DS_validation_experiments\machine_learning_concepts_checks\project\dataset_plots\generic_plots.py", line 71, in plot_series_histogram
    raise exc
  File "c:\Users\gcabreram\Documents\DS_validation_experiments\machine_learning_concepts_checks\project\dataset_plots\generic_plots.py", line 66, in plot_series_histogram
    plt.hist(self.dataframe[attribute])
  File "C:\Users\gcabreram\AppData\Local\Continuum\anaconda3\lib\site-packages\pandas\core\frame.py", line 2927, in __getitem__
    indexer = self.columns.get_loc(key)
  File "C:\Users\gcabreram\AppData\Local\Continuum\anaconda3\lib\site-packages\pandas\core\indexes\base.py", line 2659, in get_loc
    return self._engine.get_loc(self._maybe_cast_indexer(key))
  File "pandas/_libs/index.pyx", line 108, in pandas._libs.index.IndexEngine.get_loc
  File "pandas/_libs/index.pyx", line 132, in pandas._libs.index.IndexEngine.get_loc
  File "pandas/_libs/hashtable_class_helper.pxi", line 1601, in pandas._libs.hashtable.PyObjectHashTable.get_item
  File "pandas/_libs/hashtable_class_helper.pxi", line 1608, in pandas._libs.hashtable.PyObjectHashTable.get_item
KeyError: 'normal_data_1'
2019-10-28 20:29:43,809 raised exception at 2019-10-28.log: 'normal_data_1'
Traceback (most recent call last):
  File "C:\Users\gcabreram\AppData\Local\Continuum\anaconda3\lib\site-packages\pandas\core\indexes\base.py", line 2657, in get_loc
    return self._engine.get_loc(key)
  File "pandas/_libs/index.pyx", line 108, in pandas._libs.index.IndexEngine.get_loc
  File "pandas/_libs/index.pyx", line 132, in pandas._libs.index.IndexEngine.get_loc
  File "pandas/_libs/hashtable_class_helper.pxi", line 1601, in pandas._libs.hashtable.PyObjectHashTable.get_item
  File "pandas/_libs/hashtable_class_helper.pxi", line 1608, in pandas._libs.hashtable.PyObjectHashTable.get_item
KeyError: 'normal_data_1'

During handling of the above exception, another exception occurred:

Traceback (most recent call last):
  File "<ipython-input-6-156882af8b8f>", line 9, in <module>
    figsize_rows=5, figsize_cols=3)
  File "c:\Users\gcabreram\Documents\DS_validation_experiments\machine_learning_concepts_checks\project\dataset_plots\generic_plots.py", line 71, in plot_series_histogram
    raise exc
  File "c:\Users\gcabreram\Documents\DS_validation_experiments\machine_learning_concepts_checks\project\dataset_plots\generic_plots.py", line 66, in plot_series_histogram
    plt.hist(self.dataframe[attribute])
  File "C:\Users\gcabreram\AppData\Local\Continuum\anaconda3\lib\site-packages\pandas\core\frame.py", line 2927, in __getitem__
    indexer = self.columns.get_loc(key)
  File "C:\Users\gcabreram\AppData\Local\Continuum\anaconda3\lib\site-packages\pandas\core\indexes\base.py", line 2659, in get_loc
    return self._engine.get_loc(self._maybe_cast_indexer(key))
  File "pandas/_libs/index.pyx", line 108, in pandas._libs.index.IndexEngine.get_loc
  File "pandas/_libs/index.pyx", line 132, in pandas._libs.index.IndexEngine.get_loc
  File "pandas/_libs/hashtable_class_helper.pxi", line 1601, in pandas._libs.hashtable.PyObjectHashTable.get_item
  File "pandas/_libs/hashtable_class_helper.pxi", line 1608, in pandas._libs.hashtable.PyObjectHashTable.get_item
KeyError: 'normal_data_1'
